Workbook

Sheet Guide & Notes
A1: ShopNow Risk Register — User Guide & Notes
A2: ISO/IEC 27001:2022 aligned · 5x5 Matrix · Row colour auto-updates based on Risk Rating
A4: 1. Register Structure — Column Buckets
A5: Ref | B5: Column A. Unique risk identifier (e.g. R-001). Increment sequentially; never re-use a retired ID.
A6: Risk Identification | B6: Columns B-H. Captures what the risk is: ISO 27001 domain, affected information asset, the threat that could cause harm, the underlying vulnerability, a one-line risk statement, longer risk description, and existing controls.
A7: Risk Assessment | B7: Columns I-L. Quantifies the risk. Select Likelihood (I) and Impact (J) from dropdowns - Risk Score (K) and Risk Rating (L) auto-calculate. The Risk Rating cell changes colour.
A8: Risk Treatment | B8: Columns M-S. Records what will be done. Select a treatment option, document specific controls, assign an owner, set a target date, and track status. Treatment Action and Review Date complete the trail.
A9: Residual Risk | B9: Columns T-W. After treatment controls are applied, record the residual Likelihood (T) and Impact (U). Columns V and W auto-calculate the residual score and rating with colour.
A10: Notes | B10: Columns X-Y. Next Review Date and free-text for cross-references, decisions, evidence links, or audit-trail notes.
A12: 2. How to Use the Register
A13: Step 1 | B13: Enter a unique Risk ID in column A and fill columns B-H with asset, threat, vulnerability, and existing controls.
A14: Step 2 | B14: Select Likelihood (I) and Impact (J) from the dropdown menus. Score and Rating calculate instantly.
A15: Step 3 | B15: The Risk Rating cell turns green (L), yellow (M), orange (H), or red (VH) automatically.
A16: Step 4 | B16: Choose a Treatment Option (M) and document the plan in column N. Assign a Risk Owner (O) and Target Date (P).
A17: Step 5 | B17: Update Status (Q) as work progresses: Open -> In Progress -> Closed.
A18: Step 6 | B18: Once controls are implemented, select Residual Likelihood (T) and Residual Impact (U) to see the residual risk.
A19: Important | B19: Do NOT manually edit columns K, L, V, or W - these contain formulas. Overwriting will break calculations.
A21: 3. Likelihood Scale
A22: 1 — Rare | B22: Very unlikely; less than once every 10 years. e.g. major natural disaster affecting geographically diverse operations.
A23: 2 — Unlikely | B23: Could occur but not expected; once every 5-10 years. e.g. targeted attack on a non-high-profile small business.
A24: 3 — Possible | B24: Might occur at some point; once every 1-5 years. e.g. phishing email bypassing filters.
A25: 4 — Likely | B25: Will probably occur; once per year or more. e.g. credential stuffing on an internet-facing application.
A26: 5 — Almost Certain | B26: Expected to occur frequently; multiple times per year. e.g. automated scanning of unpatched public systems.
A28: 4. Impact Scale
A29: 1 — Minor | B29: Negligible disruption. Minimal financial loss. No regulatory breach. Resolved internally.
A30: 2 — Serious | B30: Minor disruption. Small financial loss (<1% revenue). Possible regulatory notice. Limited reputational impact.
A31: 3 — Severe | B31: Significant disruption (hours/days). Moderate financial loss. Possible regulatory fine. Noticeable reputational damage.
A32: 4 — Major | B32: Substantial disruption. Large financial loss. Likely regulatory investigation. Significant reputational damage.
A33: 5 — Catastrophic | B33: Existential threat. Critical financial loss. Regulatory prosecution / licence revocation. Permanent reputational damage.
A35: 5. Risk Rating & Row Colour Key
A36: L — Low (Green) | B36: Score 1-4. Monitor only. Review at next scheduled assessment. No immediate action needed.
A37: M — Medium (Yellow) | B37: Score 5-9. Address within 90 days. Assign owner and document treatment plan. Report to departmental manager.
A38: H — High (Orange) | B38: Score 10-16. Urgent action required. Escalate to senior management. Treatment plan approved and commenced within 30 days.
A39: VH — Very High (Red) | B39: Score 20-25. Immediate action. Board/executive escalation mandatory. Treat before resuming normal operations where possible.
A41: 6. Treatment Options (ISO 27005)
A42: Mitigate | B42: Implement controls to reduce likelihood and/or impact to an acceptable level. Document specific controls in column N.
A43: Accept | B43: Formally accept the risk where treatment cost exceeds benefit, or residual risk is within appetite. Requires written sign-off.
A44: Transfer | B44: Transfer financial consequence to a third party (e.g. cyber insurance, payment gateway, supplier contract). Risk itself is not transferred.
A45: Avoid | B45: Eliminate the risk by ceasing the activity that gives rise to it. Use only when risk is unacceptably high and no viable treatment exists.
A47: 7. ISO 27001:2022 Domain Quick Reference
...

Sheet Risk Matrix
B1: Risk Heat Map — 5 x 5 Matrix | J1: Lookup (formula reference — do not edit)
J2: Impact↓/LH→ | K2: 1 | L2: 2 | M2: 3 | N2: 4 | O2: 5
B3: Impact ↓ / Likelihood → | C3: 1 - Rare | D3: 2 - Unlikely | E3: 3 - Possible | F3: 4 - Likely | G3: 5 - Almost Certain | J3: 5 | K3: M | L3: M | M3: M | N3: H | O3: VH
B4: 5 - Catastrophic | C4: M | D4: M | E4: M | F4: H | G4: VH | J4: 4 | K4: M | L4: M | M4: M | N4: H | O4: H
B5: 4 - Major | C5: M | D5: M | E5: M | F5: H | G5: H | J5: 3 | K5: L | L5: M | M5: M | N5: M | O5: M
B6: 3 - Severe | C6: L | D6: M | E6: M | F6: M | G6: M | J6: 2 | K6: L | L6: L | M6: M | N6: M | O6: M
B7: 2 - Serious | C7: L | D7: L | E7: M | F7: M | G7: M | J7: 1 | K7: L | L7: L | M7: L | N7: L | O7: M
B8: 1 - Minor | C8: L | D8: L | E8: L | F8: L | G8: M
B10: Legend — Cell Colour Key
B11: L | C11: Low Risk — Monitor. Review at next scheduled cycle. No immediate action required.
B12: M | C12: Medium Risk — Mitigate within 90 days. Assign owner. Report to departmental manager.
B13: H | C13: High Risk — Urgent. Escalate to senior management. Treatment within 30 days.
B14: VH | C14: Very High Risk — Immediate action. Board-level escalation. Treat before resuming normal ops.
B17: LIKELIHOOD Description | F17: IMPACT Description
B18: Score | C18: Likelihood | D18: Description | F18: Score | G18: Impact | H18: Description
B19: 1 | C19: Rare | D19: Very unlikely to occur. No known incidents. | F19: 1 | G19: Minor | H19: Minimal disruption. No regulatory impact.
B20: 2 | C20: Unlikely | D20: Could occur but not expected in normal circumstances. | F20: 2 | G20: Serious | H20: Small operational disruption. Easily recoverable.
B21: 3 | C21: Possible | D21: Has occurred before in the organisation or industry. | F21: 3 | G21: Severe | H21: Noticeable business impact or limited financial loss.
B22: 4 | C22: Likely | D22: Expected to occur periodically. | F22: 4 | G22: Major | H22: Significant operational disruption or regulatory exposure.
B23: 5 | C23: Almost Certain | D23: Happens frequently or is inevitable without controls. | F23: 5 | G23: Catastrophic | H23: Major financial loss, legal penalties, or reputational damage.

Sheet Register Summary
A1: ShopNow Risk Register — Summary (v2)
A3: Risk Appetite Statement
A4: ShopNow accepts Low and Medium residual risk. High residual risk requires a dated treatment plan and owner sign-off. Very High residual risk is not accepted: the activity stops or escalates to the Owner immediately. Any risk whose treatment target date passes while still open escalates automatically (see Ageing flag, column AB).
A6: Register at a glance
A7: Total risks | B7: =COUNTA('Risk Register'!A5:A100)
A8: Open | B8: =COUNTIF('Risk Register'!Q5:Q100,"Open")
A9: In Progress | B9: =COUNTIF('Risk Register'!Q5:Q100,"In Progress")
A10: Closed | B10: =COUNTIF('Risk Register'!Q5:Q100,"Closed")
A11: Inherent: Very High | B11: =COUNTIF('Risk Register'!L5:L100,"VH")
A12: Inherent: High | B12: =COUNTIF('Risk Register'!L5:L100,"H")
A13: Residual above appetite (H/VH) | B13: =COUNTIF('Risk Register'!AA5:AA100,"NO - escalate")
A14: Overdue treatments | B14: =COUNTIF('Risk Register'!AB5:AB100,"OVERDUE")

Sheet Risk Register
A1: ShopNow Information Security Risk Register
A2: Aligned to ISO/IEC 27001:2022 · Annex A Controls · 5x5 Heat-Map Matrix | Row colour = inherent risk level
A3: Ref | B3: RISK IDENTIFICATION | I3: RISK ASSESSMENT | M3: RISK TREATMENT | T3: RESIDUAL RISK | X3: NOTES
A4: Risk ID | B4: ISO 27001 Domain | C4: Information Asset | D4: Threat Description | E4: Vulnerability | F4: Risk Statement | G4: Risk Description | H4: Existing Controls | I4: Likelihood | J4: Impact | K4: Risk Score | L4: Risk Rating | M4: Treatment Option | N4: Treatment Plan / Additional Controls | O4: Risk Owner | P4: Target Date | Q4: Status | R4: Treatment Action | S4: Review Date | T4: Residual Likelihood | U4: Residual Impact | V4: Residual Score | W4: Residual Rating | X4: Next Review Date | Y4: Notes / Comments | Z4: ISO 27001:2022 Annex A Controls | AA4: Residual Within Appetite? | AB4: Ageing / Escalation Flag
A5: R-001 | B5: A.6 — People Controls / A.12 — Operations Security | C5: Email System; Staff Accounts | D5: Phishing / Social Engineering | E5: Basic spam filtering only; no staff awareness training; no DMARC/SPF/DKIM | F5: A staff member discloses credentials or initiates a fraudulent payment following a phishing email, leading to account takeover and financial loss. | G5: ShopNow staff have already received phishing emails that nearly succeeded. Without advanced filtering and awareness training, a successful attack is expected within the year. | H5: Basic email spam filters; informal warnings to staff | I5: 4 - Likely | J5: 3 - Severe | K5: =IFERROR(IF(AND(I5<>"",J5<>""),VALUE(LEFT(I5,1))*VALUE(LEFT(J5,1)),""),"") | L5: =IFERROR(IF(AND(I5<>"",J5<>""),INDEX('Risk Matrix'!$K$3:$O$7,MATCH(VALUE(LEFT(J5,1)),'Risk Matrix'!$J$3:$J$7,0),MATCH(VALUE(LEFT(I5,1)),'Risk Matrix'!$K$2:$O$2,0)),""),"") | M5: Mitigate | N5: Deploy DMARC/SPF/DKIM email authentication; deliver phishing awareness training quarterly; run simulated phishing tests; establish a clear reporting channel for suspicious emails | O5: IT / Owner | P5: 46203 | Q5: In Progress | R5: Vendor evaluation underway for advanced email filtering; first training session scheduled | S5: 46188 | T5: 2 - Unlikely | U5: 2 - Serious | V5: =IFERROR(IF(AND(T5<>"",U5<>""),VALUE(LEFT(T5,1))*VALUE(LEFT(U5,1)),""),"") | W5: =IFERROR(IF(AND(T5<>"",U5<>""),INDEX('Risk Matrix'!$K$3:$O$7,MATCH(VALUE(LEFT(U5,1)),'Risk Matrix'!$J$3:$J$7,0),MATCH(VALUE(LEFT(T5,1)),'Risk Matrix'!$K$2:$O$2,0)),""),"") | X5: 46295 | Y5: Reference incidents: near-miss disclosure event noted in case study | Z5: A.5.15, A.5.17, A.8.7, A.6.3 | AA5: =IF(W5="","",IF(OR(W5="L",W5="M"),"Yes","NO - escalate")) | AB5: =IF(AND(Q5<>"Closed",P5<>"",P5<TODAY()),"OVERDUE","")
A6: R-002 | B6: A.8 — Technological Controls | C6: Public Website; Customer Database | D6: SQL Injection Attack | E6: Limited input validation; basic WAF without tuned rules; legacy code paths | F6: An attacker exploits unsanitised input on the ShopNow website to extract or modify customer database records, leading to a customer data breach. | G6: Automated SQL injection attempts have already been observed against the public site. A successful exploitation would expose customer PII and possibly payment data. | H6: Basic web application firewall (WAF) | I6: 4 - Likely | J6: 4 - Major | K6: =IFERROR(IF(AND(I6<>"",J6<>""),VALUE(LEFT(I6,1))*VALUE(LEFT(J6,1)),""),"") | L6: =IFERROR(IF(AND(I6<>"",J6<>""),INDEX('Risk Matrix'!$K$3:$O$7,MATCH(VALUE(LEFT(J6,1)),'Risk Matrix'!$J$3:$J$7,0),MATCH(VALUE(LEFT(I6,1)),'Risk Matrix'!$K$2:$O$2,0)),""),"") | M6: Mitigate | N6: Tune WAF with OWASP Core Rule Set; enforce parameterised queries in code; run quarterly vulnerability scans; commission an annual penetration test | O6: Web Developer | P6: 46218 | Q6: Open | R6: Awaiting developer capacity; vulnerability scan scheduled for Q3 | S6: 46204 | T6: 2 - Unlikely | U6: 3 - Severe | V6: =IFERROR(IF(AND(T6<>"",U6<>""),VALUE(LEFT(T6,1))*VALUE(LEFT(U6,1)),""),"") | W6: =IFERROR(IF(AND(T6<>"",U6<>""),INDEX('Risk Matrix'!$K$3:$O$7,MATCH(VALUE(LEFT(U6,1)),'Risk Matrix'!$J$3:$J$7,0),MATCH(VALUE(LEFT(T6,1)),'Risk Matrix'!$K$2:$O$2,0)),""),"") | X6: 46326 | Y6: Linked to R-005 customer data breach | Z6: A.8.25, A.8.26, A.8.8, A.8.34 | AA6: =IF(W6="","",IF(OR(W6="L",W6="M"),"Yes","NO - escalate")) | AB6: =IF(AND(Q6<>"Closed",P6<>"",P6<TODAY()),"OVERDUE","")
A7: R-003 | B7: A.5 — Organisational Controls / A.8 — Technological Controls | C7: All staff and admin accounts | D7: Credential Compromise via weak / reused passwords | E7: No documented password policy; no multi-factor authentication; password reuse common | F7: An attacker obtains a staff password through reuse, phishing, or brute force and gains unauthorised access to ShopNow systems, including the admin panel. | G7: The case study documents weak password practices as widespread. Without policy enforcement or MFA, compromise is almost certain to occur and would have catastrophic consequences if it reaches an admin account. | H7: None documented | I7: 5 - Almost Certain | J7: 5 - Catastrophic | K7: =IFERROR(IF(AND(I7<>"",J7<>""),VALUE(LEFT(I7,1))*VALUE(LEFT(J7,1)),""),"") | L7: =IFERROR(IF(AND(I7<>"",J7<>""),INDEX('Risk Matrix'!$K$3:$O$7,MATCH(VALUE(LEFT(J7,1)),'Risk Matrix'!$J$3:$J$7,0),MATCH(VALUE(LEFT(I7,1)),'Risk Matrix'!$K$2:$O$2,0)),""),"") | M7: Mitigate | N7: Enforce strong password policy (minimum 12 characters, complexity); enable MFA on all admin and email accounts; deploy a password manager for all staff | O7: IT / Owner | P7: 46173 | Q7: Open | R7: Password manager licences approved; MFA enrolment to begin week of 25 May | S7: 46167 | T7: 1 - Rare | U7: 4 - Major | V7: =IFERROR(IF(AND(T7<>"",U7<>""),VALUE(LEFT(T7,1))*VALUE(LEFT(U7,1)),""),"") | W7: =IFERROR(IF(AND(T7<>"",U7<>""),INDEX('Risk Matrix'!$K$3:$O$7,MATCH(VALUE(LEFT(U7,1)),'Risk Matrix'!$J$3:$J$7,0),MATCH(VALUE(LEFT(T7,1)),'Risk Matrix'!$K$2:$O$2,0)),""),"") | X7: 46265 | Y7: Treatment corrected from Avoid to Mitigate in v2: MFA and password policy reduce likelihood; the activity (staff accounts) continues. Owner sign-off required on residual risk acceptance. | Z7: A.5.17, A.8.2, A.8.5 | AA7: =IF(W7="","",IF(OR(W7="L",W7="M"),"Yes","NO - escalate")) | AB7: =IF(AND(Q7<>"Closed",P7<>"",P7<TODAY()),"OVERDUE","")
A8: R-004 | B8: A.8 — Technological Controls / A.17 — Business Continuity | C8: Workstations; Servers; Business Operations | D8: Ransomware / Malware Infection | E8: Basic AV only; no EDR; no network segmentation; backups not verified | F8: Ransomware encrypts ShopNow's business systems, halting operations and demanding payment, with potential permanent data loss if backups are inadequate. | G8: Small e-commerce businesses are heavily targeted by opportunistic ransomware operators. Without EDR and tested backups, recovery could take weeks and threaten business continuity. | H8: Basic anti-virus on workstations | I8: 4 - Likely | J8: 5 - Catastrophic | K8: =IFERROR(IF(AND(I8<>"",J8<>""),VALUE(LEFT(I8,1))*VALUE(LEFT(J8,1)),""),"") | L8: =IFERROR(IF(AND(I8<>"",J8<>""),INDEX('Risk Matrix'!$K$3:$O$7,MATCH(VALUE(LEFT(J8,1)),'Risk Matrix'!$J$3:$J$7,0),MATCH(VALUE(LEFT(I8,1)),'Risk Matrix'!$K$2:$O$2,0)),""),"") | M8: Mitigate | N8: Deploy endpoint detection and response (EDR); segment the network; verify offline backups weekly; document and test a recovery runbook | O8: IT / Owner | P8: 46265 | Q8: Open | R8: EDR vendor shortlist drafted; segmentation requires hosting provider conversation | S8: 46249 | T8: 2 - Unlikely | U8: 3 - Severe | V8: =IFERROR(IF(AND(T8<>"",U8<>""),VALUE(LEFT(T8,1))*VALUE(LEFT(U8,1)),""),"") | W8: =IFERROR(IF(AND(T8<>"",U8<>""),INDEX('Risk Matrix'!$K$3:$O$7,MATCH(VALUE(LEFT(U8,1)),'Risk Matrix'!$J$3:$J$7,0),MATCH(VALUE(LEFT(T8,1)),'Risk Matrix'!$K$2:$O$2,0)),""),"") | X8: 46356 | Y8: Closely linked to R-008 backup posture | Z8: A.8.7, A.8.13, A.8.14, A.5.24 | AA8: =IF(W8="","",IF(OR(W8="L",W8="M"),"Yes","NO - escalate")) | AB8: =IF(AND(Q8<>"Closed",P8<>"",P8<TODAY()),"OVERDUE","")
A9: R-005 | B9: A.8 — Technological Controls / A.10 — Cryptography | C9: Customer Database (PII, payment data) | D9: Data Breach / Exfiltration of Customer Data | E9: Limited encryption at rest; PII held locally; no DLP; partial visibility | F9: A breach exposes customer personal and payment information through SQL injection, credential compromise, or a third-party vendor incident, triggering regulatory and reputational consequences. | G9: Customer data is the most valuable asset ShopNow holds. Multiple attack pathways (R-001, R-002, R-003) could lead here. Mandatory notification laws apply in most jurisdictions. | H9: HTTPS/TLS in transit; payment processing via PCI-DSS compliant gateway | I9: 4 - Likely | J9: 5 - Catastrophic | K9: =IFERROR(IF(AND(I9<>"",J9<>""),VALUE(LEFT(I9,1))*VALUE(LEFT(J9,1)),""),"") | L9: =IFERROR(IF(AND(I9<>"",J9<>""),INDEX('Risk Matrix'!$K$3:$O$7,MATCH(VALUE(LEFT(J9,1)),'Risk Matrix'!$J$3:$J$7,0),MATCH(VALUE(LEFT(I9,1)),'Risk Matrix'!$K$2:$O$2,0)),""),"") | M9: Transfer | N9: Confirm payment gateway carries PCI-DSS Level 1 attestation; minimise PII stored locally; purchase cyber liability insurance; prepare a breach notification procedure aligned with applicable privacy laws | O9: Owner / Legal | P9: 46295 | Q9: Open | R9: Insurance broker engaged; PII minimisation review scheduled with developer | S9: 46280 | T9: 2 - Unlikely | U9: 4 - Major | V9: =IFERROR(IF(AND(T9<>"",U9<>""),VALUE(LEFT(T9,1))*VALUE(LEFT(U9,1)),""),"") | W9: =IFERROR(IF(AND(T9<>"",U9<>""),INDEX('Risk Matrix'!$K$3:$O$7,MATCH(VALUE(LEFT(U9,1)),'Risk Matrix'!$J$3:$J$7,0),MATCH(VALUE(LEFT(T9,1)),'Risk Matrix'!$K$2:$O$2,0)),""),"") | X9: 46387 | Y9: Dependent on closure of R-001, R-002, R-003 | Z9: A.8.10, A.8.11, A.8.24, A.5.31 | AA9: =IF(W9="","",IF(OR(W9="L",W9="M"),"Yes","NO - escalate")) | AB9: =IF(AND(Q9<>"Closed",P9<>"",P9<TODAY()),"OVERDUE","")
A10: R-006 | B10: A.8 — Technological Controls | C10: Public Website; Hosting Infrastructure | D10: Distributed Denial of Service (DDoS) | E10: Standard hosting plan with no specific DDoS protection; no CDN; no rate limiting | F10: A DDoS attack overwhelms ShopNow's website, causing extended downtime, lost sales during the attack window, and possible customer trust impact. | G10: DDoS-for-hire services are inexpensive and trivially deployed. Even a short outage during a sales peak (e.g. Black Friday) would have direct revenue consequences. | H10: Standard hosting plan with no specific DDoS protection | I10: 3 - Possible | J10: 3 - Severe | K10: =IFERROR(IF(AND(I10<>"",J10<>""),VALUE(LEFT(I10,1))*VALUE(LEFT(J10,1)),""),"") | L10: =IFERROR(IF(AND(I10<>"",J10<>""),INDEX('Risk Matrix'!$K$3:$O$7,MATCH(VALUE(LEFT(J10,1)),'Risk Matrix'!$J$3:$J$7,0),MATCH(VALUE(LEFT(I10,1)),'Risk Matrix'!$K$2:$O$2,0)),""),"") | M10: Mitigate | N10: Move DNS and edge traffic behind a CDN with DDoS protection (e.g. Cloudflare); set rate-limiting rules; document an incident escalation path with the hosting provider | O10: IT | P10: 46234 | Q10: Open | R10: Cloudflare quote received; migration plan drafted | S10: 46223 | T10: 1 - Rare | U10: 2 - Serious | V10: =IFERROR(IF(AND(T10<>"",U10<>""),VALUE(LEFT(T10,1))*VALUE(LEFT(U10,1)),""),"") | W10: =IFERROR(IF(AND(T10<>"",U10<>""),INDEX('Risk Matrix'!$K$3:$O$7,MATCH(VALUE(LEFT(U10,1)),'Risk Matrix'!$J$3:$J$7,0),MATCH(VALUE(LEFT(T10,1)),'Risk Matrix'!$K$2:$O$2,0)),""),"") | X10: 46326 | Y10: Treatment corrected from Transfer to Mitigate in v2: a CDN reduces likelihood and impact; no financial consequence is contractually transferred. Free CDN tier may be sufficient initially. | Z10: A.8.14, A.8.20, A.5.19 | AA10: =IF(W10="","",IF(OR(W10="L",W10="M"),"Yes","NO - escalate")) | AB10: =IF(AND(Q10<>"Closed",P10<>"",P10<TODAY()),"OVERDUE","")
A11: R-007 | B11: A.8 — Technological Controls / A.12 — Operations Security | C11: Operating Systems; Browsers; Web Server Software | D11: Exploitation of Known Vulnerabilities (unpatched CVEs) | E11: Manual updates only; no patch policy; no asset inventory; long patch windows | F11: An attacker exploits a known unpatched vulnerability on ShopNow's systems, gaining a foothold that enables further attacks (lateral movement, data theft, ransomware). | G11: Automated scanners constantly probe internet-facing systems for known CVEs. The window between disclosure and exploitation is often hours, so manual patching cannot keep up. | H11: Manual updates by staff when prompted | I11: 5 - Almost Certain | J11: 3 - Severe | K11: =IFERROR(IF(AND(I11<>"",J11<>""),VALUE(LEFT(I11,1))*VALUE(LEFT(J11,1)),""),"") | L11: =IFERROR(IF(AND(I11<>"",J11<>""),INDEX('Risk Matrix'!$K$3:$O$7,MATCH(VALUE(LEFT(J11,1)),'Risk Matrix'!$J$3:$J$7,0),MATCH(VALUE(LEFT(I11,1)),'Risk Matrix'!$K$2:$O$2,0)),""),"") | M11: Mitigate | N11: Enable automated patching for OS and browsers; maintain an asset inventory; subscribe to vendor security advisories; patch critical CVEs within 14 days | O11: IT | P11: 46203 | Q11: In Progress | R11: Asset inventory underway; automated patching enabled on three workstations as pilot | S11: 46188 | T11: 2 - Unlikely | U11: 3 - Severe | V11: =IFERROR(IF(AND(T11<>"",U11<>""),VALUE(LEFT(T11,1))*VALUE(LEFT(U11,1)),""),"") | W11: =IFERROR(IF(AND(T11<>"",U11<>""),INDEX('Risk Matrix'!$K$3:$O$7,MATCH(VALUE(LEFT(U11,1)),'Risk Matrix'!$J$3:$J$7,0),MATCH(VALUE(LEFT(T11,1)),'Risk Matrix'!$K$2:$O$2,0)),""),"") | X11: 46295 | Y11: Quick win — low cost, high coverage | Z11: A.8.8, A.8.9, A.8.19 | AA11: =IF(W11="","",IF(OR(W11="L",W11="M"),"Yes","NO - escalate")) | AB11: =IF(AND(Q11<>"Closed",P11<>"",P11<TODAY()),"OVERDUE","")
A12: R-008 | B12: A.17 — Business Continuity / A.8 — Technological Controls | C12: All business and customer data | D12: Data Loss (ransomware, hardware failure, human error) | E12: Ad-hoc local backups; no documented schedule; no restoration testing; no offsite copy | F12: ShopNow loses business or customer data due to ransomware, hardware failure, or accidental deletion, with no reliable restoration path, threatening continued operations. | G12: Backups exist informally but have never been tested. Without 3-2-1 discipline and tested restores, the existence of backup files does not guarantee recovery. | H12: Ad-hoc local backups; no documented schedule | I12: 3 - Possible | J12: 5 - Catastrophic | K12: =IFERROR(IF(AND(I12<>"",J12<>""),VALUE(LEFT(I12,1))*VALUE(LEFT(J12,1)),""),"") | L12: =IFERROR(IF(AND(I12<>"",J12<>""),INDEX('Risk Matrix'!$K$3:$O$7,MATCH(VALUE(LEFT(J12,1)),'Risk Matrix'!$J$3:$J$7,0),MATCH(VALUE(LEFT(I12,1)),'Risk Matrix'!$K$2:$O$2,0)),""),"") | M12: Mitigate | N12: Implement 3-2-1 backup strategy (3 copies, 2 media, 1 offsite); automate daily backups; test restoration monthly; document recovery time and recovery point objectives | O12: IT / Owner | P12: 46218 | Q12: Open | R12: Cloud backup provider selected; first restoration test scheduled August | S12: 46208 | T12: 2 - Unlikely | U12: 2 - Serious | V12: =IFERROR(IF(AND(T12<>"",U12<>""),VALUE(LEFT(T12,1))*VALUE(LEFT(U12,1)),""),"") | W12: =IFERROR(IF(AND(T12<>"",U12<>""),INDEX('Risk Matrix'!$K$3:$O$7,MATCH(VALUE(LEFT(U12,1)),'Risk Matrix'!$J$3:$J$7,0),MATCH(VALUE(LEFT(T12,1)),'Risk Matrix'!$K$2:$O$2,0)),""),"") | X12: 46310 | Y12: Recovery enables resilience for R-004 ransomware | Z12: A.8.13, A.8.14, A.5.30 | AA12: =IF(W12="","",IF(OR(W12="L",W12="M"),"Yes","NO - escalate")) | AB12: =IF(AND(Q12<>"Closed",P12<>"",P12<TODAY()),"OVERDUE","")
A13: R-009 | B13: A.5 — Organisational Controls | C13: Payment Gateway; Hosting Provider; Key Suppliers | D13: Third-Party / Supplier Failure or Breach | E13: No supplier security assessment; no contractual security clauses; single payment gateway with no fallback | F13: A key supplier such as the payment gateway suffers a breach or outage, exposing ShopNow customer data or halting checkout, with ShopNow carrying the customer and regulatory impact. | G13: ShopNow depends on third parties for payment processing and hosting but has never assessed their security posture. The 2019 AMCA breach that exposed millions of Quest Diagnostics patients is the pattern: the vendor fails, the brand pays. | H13: Payment processing via PCI-DSS compliant gateway (attestation not verified) | I13: 3 - Possible | J13: 4 - Major | K13: =IFERROR(IF(AND(I13<>"",J13<>""),VALUE(LEFT(I13,1))*VALUE(LEFT(J13,1)),""),"") | L13: =IFERROR(IF(AND(I13<>"",J13<>""),INDEX('Risk Matrix'!$K$3:$O$7,MATCH(VALUE(LEFT(J13,1)),'Risk Matrix'!$J$3:$J$7,0),MATCH(VALUE(LEFT(I13,1)),'Risk Matrix'!$K$2:$O$2,0)),""),"") | M13: Mitigate | N13: Verify gateway PCI-DSS Level 1 attestation annually; add security clauses and breach-notification terms to supplier contracts; tier suppliers by data access; assess critical suppliers before renewal | O13: Owner / Legal | P13: 46371 | Q13: Open | R13: Supplier inventory started; attestation request drafted | S13: 46341 | T13: 2 - Unlikely | U13: 3 - Severe | V13: =IFERROR(IF(AND(T13<>"",U13<>""),VALUE(LEFT(T13,1))*VALUE(LEFT(U13,1)),""),"") | W13: =IFERROR(IF(AND(T13<>"",U13<>""),INDEX('Risk Matrix'!$K$3:$O$7,MATCH(VALUE(LEFT(U13,1)),'Risk Matrix'!$J$3:$J$7,0),MATCH(VALUE(LEFT(T13,1)),'Risk Matrix'!$K$2:$O$2,0)),""),"") | X13: 46446 | Y13: New in v2. Links to R-005: a supplier breach is one path to customer data exposure. | Z13: A.5.19, A.5.20, A.5.21, A.5.22 | AA13: =IF(W13="","",IF(OR(W13="L",W13="M"),"Yes","NO - escalate")) | AB13: =IF(AND(Q13<>"Closed",P13<>"",P13<TODAY()),"OVERDUE","")
A14: R-010 | B14: A.8 — Technological Controls | C14: Admin Panel; Privileged Accounts | D14: Privileged Access Misuse / Excessive Access | E14: No access reviews; shared admin credentials in use; leavers’ access not promptly revoked | F14: A staff member or ex-staff member uses excessive or stale privileged access to view, alter, or delete ShopNow data without detection. | G14: Privileged accounts are the highest-value target and the least governed at ShopNow. Without periodic access reviews and joiner-mover-leaver discipline, excessive access accumulates silently. | H14: Individual staff logins for day-to-day systems; admin access informal | I14: 3 - Possible | J14: 4 - Major | K14: =IFERROR(IF(AND(I14<>"",J14<>""),VALUE(LEFT(I14,1))*VALUE(LEFT(J14,1)),""),"") | L14: =IFERROR(IF(AND(I14<>"",J14<>""),INDEX('Risk Matrix'!$K$3:$O$7,MATCH(VALUE(LEFT(J14,1)),'Risk Matrix'!$J$3:$J$7,0),MATCH(VALUE(LEFT(I14,1)),'Risk Matrix'!$K$2:$O$2,0)),""),"") | M14: Mitigate | N14: Remove shared admin credentials; enforce least privilege; quarterly privileged access reviews; same-day access revocation for leavers; log and alert on admin actions | O14: IT / Owner | P14: 46356 | Q14: Open | R14: Privileged account inventory to be compiled | S14: 46327 | T14: 2 - Unlikely | U14: 3 - Severe | V14: =IFERROR(IF(AND(T14<>"",U14<>""),VALUE(LEFT(T14,1))*VALUE(LEFT(U14,1)),""),"") | W14: =IFERROR(IF(AND(T14<>"",U14<>""),INDEX('Risk Matrix'!$K$3:$O$7,MATCH(VALUE(LEFT(U14,1)),'Risk Matrix'!$J$3:$J$7,0),MATCH(VALUE(LEFT(T14,1)),'Risk Matrix'!$K$2:$O$2,0)),""),"") | X14: 46418 | Y14: New in v2. Supports closure of R-003 (credential risk) once MFA and access reviews are both in place. | Z14: A.5.15, A.8.2, A.8.3, A.8.15 | AA14: =IF(W14="","",IF(OR(W14="L",W14="M"),"Yes","NO - escalate")) | AB14: =IF(AND(Q14<>"Closed",P14<>"",P14<TODAY()),"OVERDUE","")
A15: R-011 | B15: A.5 — Organisational Controls | C15: Customer Personal Information; Business Reputation | D15: Privacy / Regulatory Non-Compliance (PIPEDA) | E15: No privacy policy review; no breach response procedure; staff unaware of breach reporting duties | F15: ShopNow fails to meet its privacy obligations for customer personal information, resulting in a regulatory complaint, mandatory breach reporting failures, fines, and loss of customer trust. | G15: Canadian private-sector privacy law (PIPEDA) requires safeguards, breach records, and reporting of breaches posing a real risk of significant harm. ShopNow currently has no documented breach procedure and no single owner for privacy. | H15: Privacy policy published on website (not reviewed since launch) | I15: 3 - Possible | J15: 3 - Severe | K15: =IFERROR(IF(AND(I15<>"",J15<>""),VALUE(LEFT(I15,1))*VALUE(LEFT(J15,1)),""),"") | L15: =IFERROR(IF(AND(I15<>"",J15<>""),INDEX('Risk Matrix'!$K$3:$O$7,MATCH(VALUE(LEFT(J15,1)),'Risk Matrix'!$J$3:$J$7,0),MATCH(VALUE(LEFT(I15,1)),'Risk Matrix'!$K$2:$O$2,0)),""),"") | M15: Mitigate | N15: Appoint a privacy lead; document a breach response and notification procedure; keep a breach record register; review the privacy policy annually; train staff on handling personal information | O15: Owner / Legal | P15: 46387 | Q15: Open | R15: Privacy lead to be nominated | S15: 46357 | T15: 2 - Unlikely | U15: 2 - Serious | V15: =IFERROR(IF(AND(T15<>"",U15<>""),VALUE(LEFT(T15,1))*VALUE(LEFT(U15,1)),""),"") | W15: =IFERROR(IF(AND(T15<>"",U15<>""),INDEX('Risk Matrix'!$K$3:$O$7,MATCH(VALUE(LEFT(U15,1)),'Risk Matrix'!$J$3:$J$7,0),MATCH(VALUE(LEFT(T15,1)),'Risk Matrix'!$K$2:$O$2,0)),""),"") | X15: 46477 | Y15: New in v2. Consequence risk of R-005: a breach without a procedure turns an incident into a compliance failure. | Z15: A.5.31, A.5.33, A.5.34, A.5.36 | AA15: =IF(W15="","",IF(OR(W15="L",W15="M"),"Yes","NO - escalate")) | AB15: =IF(AND(Q15<>"Closed",P15<>"",P15<TODAY()),"OVERDUE","")
